Workbook

Sheet 日報
A1: 日報（右の緑枠をコピーして課長に送る）
G2: ▼ ここをコピー（G3〜G53） | I2: 集計（自動・触らない） | L2: ヨミ一覧（自動）
A3: 報告日 | B3: =MAX(実績入力!A5:A204) | C3: ← 自動で最新の入力日。別の日を出すときは日付を上書き | G3: =TEXT($B$3,"m/d") | I3: 経過営業日 | J3: =IF(ISNUMBER(設定!B8),設定!B8,NETWORKDAYS(設定!B5,$B$3,設定!$A$14:$A$60)) | L3: =設定!B4 | M3: =IF(L3="",0,1)
G4: ="【"&設定!B2&"】" | I4: 自アポ目標 | J4: =設定!B7 | L4: =IF(B8="","",設定!$B$3&"："&A8&B8&IF(C8="",""," ¥"&TEXT(C8,"#,##0"))) | M4: =M3+IF(L4="",0,1)
A5: 今日読める案件（ヨミ） | G5: 自アポ | I5: 自アポ実績（累計） | J5: =SUMIFS(実績入力!$B$5:$B$204,実績入力!$A$5:$A$204,">="&設定!$B$5,実績入力!$A$5:$A$204,"<="&$B$3) | L5: =IF(B9="","",設定!$B$3&"："&A9&B9&IF(C9="",""," ¥"&TEXT(C9,"#,##0"))) | M5: =M4+IF(L5="",0,1)
A6: =設定!B4 | G6: ="目標/実績/今日までの乖離（"&J3&"営業日）" | I6: 今日までの目標 | J6: =IF(設定!B9=0,0,J3*J4/設定!B9) | L6: =IF(B10="","",設定!$B$3&"："&A10&B10&IF(C10="",""," ¥"&TEXT(C10,"#,##0"))) | M6: =M5+IF(L6="",0,1)
A7: ランク | B7: 会社名 | C7: 金額（円） | G7: =J4&"/"&J5&"/"&IF(J7>0,"+","")&J7 | I7: 乖離 | J7: =ROUND(J5-J6,1) | L7: =IF(B11="","",設定!$B$3&"："&A11&B11&IF(C11="",""," ¥"&TEXT(C11,"#,##0"))) | M7: =M6+IF(L7="",0,1)
A8: ▲ | B8: 株式会社サンプル | C8: 500000 | I8: 日次訪問数 | J8: =SUMIFS(実績入力!$C$5:$C$204,実績入力!$A$5:$A$204,$B$3)+SUMIFS(実績入力!$D$5:$D$204,実績入力!$A$5:$A$204,$B$3)+SUMIFS(実績入力!$E$5:$E$204,実績入力!$A$5:$A$204,$B$3) | L8: =IF(B12="","",設定!$B$3&"："&A12&B12&IF(C12="",""," ¥"&TEXT(C12,"#,##0"))) | M8: =M7+IF(L8="",0,1)
I9: 累計訪問数 | J9: =SUMIFS(実績入力!$C$5:$C$204,実績入力!$A$5:$A$204,">="&設定!$B$5,実績入力!$A$5:$A$204,"<="&$B$3)+SUMIFS(実績入力!$D$5:$D$204,実績入力!$A$5:$A$204,">="&設定!$B$5,実績入力!$A$5:$A$204,"<="&$B$3)+SUMIFS(実績入力!$E$5:$E$204,実績入力!$A$5:$A$204,">="&設定!$B$5,実績入力!$A$5:$A$204,"<="&$B$3) | L9: =IF(B13="","",設定!$B$3&"："&A13&B13&IF(C13="",""," ¥"&TEXT(C13,"#,##0"))) | M9: =M8+IF(L9="",0,1)
G10: 日次訪問数（新規＋提案＋クロ） | I10: 日次新規訪問 | J10: =SUMIFS(実績入力!$C$5:$C$204,実績入力!$A$5:$A$204,$B$3) | L10: =設定!B10 | M10: =M9+IF(L10="",0,1)
G11: =J8&"件" | I11: 日次有効提案 | J11: =SUMIFS(実績入力!$G$5:$G$204,実績入力!$A$5:$A$204,$B$3) | L11: =IF(B17="","",設定!$B$3&"："&A17&B17&IF(C17="",""," ¥"&TEXT(C17,"#,##0"))) | M11: =M10+IF(L11="",0,1)
G12: 累計訪問数（新規＋提案＋クロ） | I12: 累計新規訪問 | J12: =SUMIFS(実績入力!$C$5:$C$204,実績入力!$A$5:$A$204,">="&設定!$B$5,実績入力!$A$5:$A$204,"<="&$B$3) | L12: =IF(B18="","",設定!$B$3&"："&A18&B18&IF(C18="",""," ¥"&TEXT(C18,"#,##0"))) | M12: =M11+IF(L12="",0,1)
G13: =J9&"件" | I13: 累計有効提案 | J13: =SUMIFS(実績入力!$G$5:$G$204,実績入力!$A$5:$A$204,">="&設定!$B$5,実績入力!$A$5:$A$204,"<="&$B$3) | L13: =IF(B19="","",設定!$B$3&"："&A19&B19&IF(C19="",""," ¥"&TEXT(C19,"#,##0"))) | M13: =M12+IF(L13="",0,1)
I14: 現在のLTV | J14: =N(設定!B11)+SUMIFS(実績入力!$K$5:$K$204,実績入力!$A$5:$A$204,">="&設定!$B$5,実績入力!$A$5:$A$204,"<="&$B$3)+SUMIFS(実績入力!$L$5:$L$204,実績入力!$A$5:$A$204,">="&設定!$B$5,実績入力!$A$5:$A$204,"<="&$B$3) | L14: =IF(B20="","",設定!$B$3&"："&A20&B20&IF(C20="",""," ¥"&TEXT(C20,"#,##0"))) | M14: =M13+IF(L14="",0,1)
A15: =設定!B10 | G15: 日次有効提案取得率 | I15: 累計CKPI | J15: =SUMIFS(実績入力!$I$5:$I$204,実績入力!$A$5:$A$204,">="&設定!$B$5,実績入力!$A$5:$A$204,"<="&$B$3) | L15: =IF(B21="","",設定!$B$3&"："&A21&B21&IF(C21="",""," ¥"&TEXT(C21,"#,##0"))) | M15: =M14+IF(L15="",0,1)
A16: ランク | B16: 会社名 | C16: 金額（円） | G16: ="新規訪問数："&J10&"件" | I16: 日次取次店 | J16: =SUMIFS(実績入力!$J$5:$J$204,実績入力!$A$5:$A$204,$B$3) | L16: =IF(B22="","",設定!$B$3&"："&A22&B22&IF(C22="",""," ¥"&TEXT(C22,"#,##0"))) | M16: =M15+IF(L16="",0,1)
A17: 〇 | B17: 株式会社テスト | C17: 300000 | G17: ="有効提案取得数："&J11&"件" | I17: 累計取次店 | J17: =SUMIFS(実績入力!$J$5:$J$204,実績入力!$A$5:$A$204,">="&設定!$B$5,実績入力!$A$5:$A$204,"<="&$B$3)
G18: ="有効提案率："&IF(J10=0,"-",TEXT(J11/J10*100,"0.0"))&"％" | I18: 翌日提案予定 | J18: =SUMIFS(実績入力!$M$5:$M$204,実績入力!$A$5:$A$204,$B$3)
I19: 翌日クロ予定 | J19: =SUMIFS(実績入力!$N$5:$N$204,実績入力!$A$5:$A$204,$B$3)
G20: 累計有効提案取得率
G21: ="新規訪問数："&J12&"件"
G22: ="有効提案取得数："&J13&"件"
G23: ="有効提案率："&IF(J12=0,"-",TEXT(J13/J12*100,"0.0"))&"％"
A24: ※8行目・17行目は入力例。空欄の行は日報に出ません（各最大6件）
G25: 現在のLTV
A26: 使い方 | G26: ="¥"&TEXT(J14,"#,##0")
A27: ①「設定」シートで氏名・期間・自アポ目標を入れる（最初だけ）
A28: ②「実績入力」シートに今日の行を追加して数字を入れる | G28: 累計CKPIマッチング数
A29: ③ このシートの黄色欄にヨミ案件を入れる（ユニーク／クロスセル） | G29: =J15&"件"
A30: ④ 右の緑枠（G3〜G53）を選択 → Ctrl+C → 報告先に貼り付け
A31: 黄色＝入力欄 / 青字＝手入力値 / それ以外は自動計算 | G31: 日次取次店開拓数
G32: =J16&"件"
G33: 累計取次店開拓数
G34: =J17&"件"
G36: 【翌日の予定・ヨミ】
G37: ="■提案予定数："&J18&"件"
G38: ="■クロ予定数："&J19&"件"
G39: ■今日読める案件バイネーム
G40: =IFERROR(INDEX($L$3:$L$16,MATCH(1,$M$3:$M$16,0)),"")
G41: =IFERROR(INDEX($L$3:$L$16,MATCH(2,$M$3:$M$16,0)),"")
...

Sheet 設定
A1: 設定（最初に一度だけ入力・期間が変わったら更新）
A2: 氏名 | B2: 杉本賢亮 | C2: 日報の【】内に表示
A3: 短縮名 | B3: 杉本 | C3: ヨミ案件の「杉本：」に表示
A4: ヨミ区分① | B4: ユニーク | C4: 「今日読める案件バイネーム」の1つ目の見出し
A5: 期間開始日 | B5: 46266 | C5: 累計・乖離の集計開始日
A6: 期間終了日 | B6: 46295 | C6: 累計・乖離の集計終了日
A7: 自アポ目標（期間） | B7: 20 | C7: 期間全体の自アポ目標件数（例の値。書き換えてください）
A8: 経過営業日（手入力） | C8: 空欄なら自動計算（土日・下の祝日を除く）。数字を入れるとそちら優先
A9: 期間営業日数 | B9: =NETWORKDAYS(B5,B6,$A$14:$A$60) | C9: 自動計算
A10: ヨミ区分② | B10: クロスセル | C10: 「今日読める案件バイネーム」の2つ目の見出し
A11: LTV繰越額（円） | B11: 0 | C11: 期間開始日より前の受注金額合計。LTV＝繰越額＋期間中のユニーク受注＋クロスセル受注
A13: 祝日・会社休日（営業日計算で除外） | C13: 出典：内閣府「国民の祝日について」。会社休日は空いている行に追加してください
A14: 46023
A15: 46034
A16: 46064
A17: 46076
A18: 46101
A19: 46141
A20: 46146
A21: 46147
A22: 46148
A23: 46223
A24: 46245
A25: 46286
... A46: 46714

Sheet 実績入力
A1: 実績入力（1日1行・黄色セルに今日の数字を入れる）
A2: ※5行目は入力例です。使い始める前に数字を消すか、実際の数字に書き換えてください。灰色の列は自動計算。
A4: 日付 | B4: 自アポ獲得数 | C4: 新規訪問数 | D4: 提案訪問数 | E4: クロ訪問数 | F4: 日次訪問数計 | G4: 有効提案取得数 | H4: 有効提案率 | I4: CKPIマッチング数 | J4: 取次店開拓数 | K4: ユニーク受注金額（円） | L4: クロスセル受注金額（円） | M4: 翌日 提案予定数 | N4: 翌日 クロ予定数 | O4: メモ
A5: 46294 | B5: 1 | C5: 3 | D5: 2 | E5: 1 | F5: =IF(A5="","",SUM(C5:E5)) | G5: 2 | H5: =IF(OR(A5="",N(C5)=0),"",G5/C5) | I5: 1 | J5: 0 | K5: 800000 | L5: 400000 | M5: 10 | N5: 1 | O5: 入力例
F6: =IF(A6="","",SUM(C6:E6)) | H6: =IF(OR(A6="",N(C6)=0),"",G6/C6)
F7: =IF(A7="","",SUM(C7:E7)) | H7: =IF(OR(A7="",N(C7)=0),"",G7/C7)
F8: =IF(A8="","",SUM(C8:E8)) | H8: =IF(OR(A8="",N(C8)=0),"",G8/C8)
F9: =IF(A9="","",SUM(C9:E9)) | H9: =IF(OR(A9="",N(C9)=0),"",G9/C9)
F10: =IF(A10="","",SUM(C10:E10)) | H10: =IF(OR(A10="",N(C10)=0),"",G10/C10)
F11: =IF(A11="","",SUM(C11:E11)) | H11: =IF(OR(A11="",N(C11)=0),"",G11/C11)
F12: =IF(A12="","",SUM(C12:E12)) | H12: =IF(OR(A12="",N(C12)=0),"",G12/C12)
F13: =IF(A13="","",SUM(C13:E13)) | H13: =IF(OR(A13="",N(C13)=0),"",G13/C13)
F14: =IF(A14="","",SUM(C14:E14)) | H14: =IF(OR(A14="",N(C14)=0),"",G14/C14)
F15: =IF(A15="","",SUM(C15:E15)) | H15: =IF(OR(A15="",N(C15)=0),"",G15/C15)
F16: =IF(A16="","",SUM(C16:E16)) | H16: =IF(OR(A16="",N(C16)=0),"",G16/C16)
F17: =IF(A17="","",SUM(C17:E17)) | H17: =IF(OR(A17="",N(C17)=0),"",G17/C17)
... F204: =IF(A204="","",SUM(C204:E204)) | H204: =IF(OR(A204="",N(C204)=0),"",G204/C204)
